Workbook

Sheet ASENTAMIENTOS
A1: MODELO WINKLER CORREGIDO — ASENTAMIENTOS POR NODO
A2: ⚡ Ingrese el asentamiento en la columna E (en mm). Las demás columnas son referencia del modelo.
A4: NODO | B4: X (mm) | C4: Y (mm) | D4: DESCRIPCIÓN | E4: ASENTAMIENTO (mm) | F4: NOTAS
A5: 1 | B5: -14600.9 | C5: -9526.3 | E5: 0
A6: 2 | B6: 14600.9 | C6: -9526.3 | E6: 0
A7: 3 | B7: -17776.3 | C7: -4026.3 | E7: 0
A8: 4 | B8: -15026.3 | C8: 736.9 | E8: 0
A9: 5 | B9: -12276.3 | C9: 5500 | E9: 0
A10: 6 | B10: -8250 | C10: -9526.3 | E10: 0
A11: 7 | B11: -5500 | C11: -4763.1 | E11: 0
A12: 8 | B12: -2750 | C12: 0 | E12: 0
A13: 9 | B13: 2750 | C13: 0 | E13: 0
A14: 10 | B14: 5500 | C14: -4763.1 | E14: 0
A15: 11 | B15: 8250 | C15: -9526.3 | E15: 0
A16: 12 | B16: 17776.3 | C16: -4026.3 | E16: 0
... A98: 109 | B98: -3553.8 | C98: 14000 | E98: 0
A101: 🟡 Celda amarilla = dato de entrada (ingrese asentamiento en mm) | 🔵 Texto azul = identificador de nodo | Coordenadas en mm (sistema del modelo ETABS)

Sheet DIFERENCIALES
A1: DIFERENCIAL DE ASENTAMIENTOS ENTRE NODOS CONECTADOS
A2: Los asentamientos se leen automáticamente de la hoja ASENTAMIENTOS (columna E). La distorsión angular = Δs / L. | L2: Límite admisible (1/n): | M2: 500
L3: ↑ Cambiar según norma (ej: 300, 500, 600)
A4: VIGA / TRAMO | B4: NODO i | C4: NODO j | D4: Xi (mm) [Coord. i] | E4: Yi (mm) [Coord. i] | F4: Xj (mm) [Coord. j] | G4: Yj (mm) [Coord. j] | H4: L (mm) =√((Xj-Xi)²+(Yj-Yi)²) | I4: δi (mm) [Asent. Nodo i] | J4: δj (mm) [Asent. Nodo j] | K4: Δs = |δi - δj| (mm) | L4: Δs / L [Dist. Angular] | M4: LÍMITE 1/n_adm | N4: ¿CUMPLE?
A5: C1↔C3 | B5: =ASENTAMIENTOS!A5 -> 1 | C5: =ASENTAMIENTOS!A7 -> 3 | D5: =COORDENADAS!B2 -> -14600.9 | E5: =COORDENADAS!C2 -> -9526.3 | F5: =COORDENADAS!B4 -> -17776.3 | G5: =COORDENADAS!C4 -> -4026.3 | H5: =SQRT((F5-D5)^2+(G5-E5)^2) -> 6350.8397 | I5: =ASENTAMIENTOS!E5 -> 0 | J5: =ASENTAMIENTOS!E7 -> 0 | K5: =ABS(I5-J5) -> 0 | L5: =IF(H5>0,K5/H5,"") -> 0 | M5: =IF($M$2>0,1/$M$2,"") -> 0.002 | N5: =IF(L5="","—",IF(L5<=M5,"✔ OK","✘ EXCEDE")) -> ✔ OK
A6: C1↔C6 | B6: =ASENTAMIENTOS!A5 -> 1 | C6: =ASENTAMIENTOS!A10 -> 6 | D6: =COORDENADAS!B2 -> -14600.9 | E6: =COORDENADAS!C2 -> -9526.3 | F6: =COORDENADAS!B7 -> -8250 | G6: =COORDENADAS!C7 -> -9526.3 | H6: =SQRT((F6-D6)^2+(G6-E6)^2) -> 6350.9 | I6: =ASENTAMIENTOS!E5 -> 0 | J6: =ASENTAMIENTOS!E10 -> 0 | K6: =ABS(I6-J6) -> 0 | L6: =IF(H6>0,K6/H6,"") -> 0 | M6: =IF($M$2>0,1/$M$2,"") -> 0.002 | N6: =IF(L6="","—",IF(L6<=M6,"✔ OK","✘ EXCEDE")) -> ✔ OK
A7: C1↔C19 | B7: =ASENTAMIENTOS!A5 -> 1 | C7: =ASENTAMIENTOS!A23 -> 19 | D7: =COORDENADAS!B2 -> -14600.9 | E7: =COORDENADAS!C2 -> -9526.3 | F7: =COORDENADAS!B20 -> -13013.165 | G7: =COORDENADAS!C20 -> -6776.2915 | H7: =SQRT((F7-D7)^2+(G7-E7)^2) -> 3175.4447 | I7: =ASENTAMIENTOS!E5 -> 0 | J7: =ASENTAMIENTOS!E23 -> 0 | K7: =ABS(I7-J7) -> 0 | L7: =IF(H7>0,K7/H7,"") -> 0 | M7: =IF($M$2>0,1/$M$2,"") -> 0.002 | N7: =IF(L7="","—",IF(L7<=M7,"✔ OK","✘ EXCEDE")) -> ✔ OK
A8: C2↔C11 | B8: =ASENTAMIENTOS!A6 -> 2 | C8: =ASENTAMIENTOS!A15 -> 11 | D8: =COORDENADAS!B3 -> 14600.9 | E8: =COORDENADAS!C3 -> -9526.3 | F8: =COORDENADAS!B12 -> 8250 | G8: =COORDENADAS!C12 -> -9526.3 | H8: =SQRT((F8-D8)^2+(G8-E8)^2) -> 6350.9 | I8: =ASENTAMIENTOS!E6 -> 0 | J8: =ASENTAMIENTOS!E15 -> 0 | K8: =ABS(I8-J8) -> 0 | L8: =IF(H8>0,K8/H8,"") -> 0 | M8: =IF($M$2>0,1/$M$2,"") -> 0.002 | N8: =IF(L8="","—",IF(L8<=M8,"✔ OK","✘ EXCEDE")) -> ✔ OK
A9: C2↔C12 | B9: =ASENTAMIENTOS!A6 -> 2 | C9: =ASENTAMIENTOS!A16 -> 12 | D9: =COORDENADAS!B3 -> 14600.9 | E9: =COORDENADAS!C3 -> -9526.3 | F9: =COORDENADAS!B13 -> 17776.3 | G9: =COORDENADAS!C13 -> -4026.3 | H9: =SQRT((F9-D9)^2+(G9-E9)^2) -> 6350.8397 | I9: =ASENTAMIENTOS!E6 -> 0 | J9: =ASENTAMIENTOS!E16 -> 0 | K9: =ABS(I9-J9) -> 0 | L9: =IF(H9>0,K9/H9,"") -> 0 | M9: =IF($M$2>0,1/$M$2,"") -> 0.002 | N9: =IF(L9="","—",IF(L9<=M9,"✔ OK","✘ EXCEDE")) -> ✔ OK
A10: C2↔C26 | B10: =ASENTAMIENTOS!A6 -> 2 | C10: =ASENTAMIENTOS!A30 -> 26 | D10: =COORDENADAS!B3 -> 14600.9 | E10: =COORDENADAS!C3 -> -9526.3 | F10: =COORDENADAS!B27 -> 13013.165 | G10: =COORDENADAS!C27 -> -6776.2915 | H10: =SQRT((F10-D10)^2+(G10-E10)^2) -> 3175.4447 | I10: =ASENTAMIENTOS!E6 -> 0 | J10: =ASENTAMIENTOS!E30 -> 0 | K10: =ABS(I10-J10) -> 0 | L10: =IF(H10>0,K10/H10,"") -> 0 | M10: =IF($M$2>0,1/$M$2,"") -> 0.002 | N10: =IF(L10="","—",IF(L10<=M10,"✔ OK","✘ EXCEDE")) -> ✔ OK
A11: C3↔C4 | B11: =ASENTAMIENTOS!A7 -> 3 | C11: =ASENTAMIENTOS!A8 -> 4 | D11: =COORDENADAS!B4 -> -17776.3 | E11: =COORDENADAS!C4 -> -4026.3 | F11: =COORDENADAS!B5 -> -15026.3 | G11: =COORDENADAS!C5 -> 736.9 | H11: =SQRT((F11-D11)^2+(G11-E11)^2) -> 5500.0522 | I11: =ASENTAMIENTOS!E7 -> 0 | J11: =ASENTAMIENTOS!E8 -> 0 | K11: =ABS(I11-J11) -> 0 | L11: =IF(H11>0,K11/H11,"") -> 0 | M11: =IF($M$2>0,1/$M$2,"") -> 0.002 | N11: =IF(L11="","—",IF(L11<=M11,"✔ OK","✘ EXCEDE")) -> ✔ OK
A12: C3↔C19 | B12: =ASENTAMIENTOS!A7 -> 3 | C12: =ASENTAMIENTOS!A23 -> 19 | D12: =COORDENADAS!B4 -> -17776.3 | E12: =COORDENADAS!C4 -> -4026.3 | F12: =COORDENADAS!B20 -> -13013.165 | G12: =COORDENADAS!C20 -> -6776.2915 | H12: =SQRT((F12-D12)^2+(G12-E12)^2) -> 5499.9917 | I12: =ASENTAMIENTOS!E7 -> 0 | J12: =ASENTAMIENTOS!E23 -> 0 | K12: =ABS(I12-J12) -> 0 | L12: =IF(H12>0,K12/H12,"") -> 0 | M12: =IF($M$2>0,1/$M$2,"") -> 0.002 | N12: =IF(L12="","—",IF(L12<=M12,"✔ OK","✘ EXCEDE")) -> ✔ OK
A13: C4↔C5 | B13: =ASENTAMIENTOS!A8 -> 4 | C13: =ASENTAMIENTOS!A9 -> 5 | D13: =COORDENADAS!B5 -> -15026.3 | E13: =COORDENADAS!C5 -> 736.9 | F13: =COORDENADAS!B6 -> -12276.3 | G13: =COORDENADAS!C6 -> 5500 | H13: =SQRT((F13-D13)^2+(G13-E13)^2) -> 5499.9656 | I13: =ASENTAMIENTOS!E8 -> 0 | J13: =ASENTAMIENTOS!E9 -> 0 | K13: =ABS(I13-J13) -> 0 | L13: =IF(H13>0,K13/H13,"") -> 0 | M13: =IF($M$2>0,1/$M$2,"") -> 0.002 | N13: =IF(L13="","—",IF(L13<=M13,"✔ OK","✘ EXCEDE")) -> ✔ OK
A14: C4↔C20 | B14: =ASENTAMIENTOS!A8 -> 4 | C14: =ASENTAMIENTOS!A24 -> 20 | D14: =COORDENADAS!B5 -> -15026.3 | E14: =COORDENADAS!C5 -> 736.9 | F14: =COORDENADAS!B21 -> -10263.117 | G14: =COORDENADAS!C21 -> -2013.119 | H14: =SQRT((F14-D14)^2+(G14-E14)^2) -> 5500.047 | I14: =ASENTAMIENTOS!E8 -> 0 | J14: =ASENTAMIENTOS!E24 -> 0 | K14: =ABS(I14-J14) -> 0 | L14: =IF(H14>0,K14/H14,"") -> 0 | M14: =IF($M$2>0,1/$M$2,"") -> 0.002 | N14: =IF(L14="","—",IF(L14<=M14,"✔ OK","✘ EXCEDE")) -> ✔ OK
A15: C5↔C17 | B15: =ASENTAMIENTOS!A9 -> 5 | C15: =ASENTAMIENTOS!A21 -> 17 | D15: =COORDENADAS!B6 -> -12276.3 | E15: =COORDENADAS!C6 -> 5500 | F15: =COORDENADAS!B18 -> -7513.1 | G15: =COORDENADAS!C18 -> 8250 | H15: =SQRT((F15-D15)^2+(G15-E15)^2) -> 5500.0522 | I15: =ASENTAMIENTOS!E9 -> 0 | J15: =ASENTAMIENTOS!E21 -> 0 | K15: =ABS(I15-J15) -> 0 | L15: =IF(H15>0,K15/H15,"") -> 0 | M15: =IF($M$2>0,1/$M$2,"") -> 0.002 | N15: =IF(L15="","—",IF(L15<=M15,"✔ OK","✘ EXCEDE")) -> ✔ OK
A16: C5↔C21 | B16: =ASENTAMIENTOS!A9 -> 5 | C16: =ASENTAMIENTOS!A25 -> 21 | D16: =COORDENADAS!B6 -> -12276.3 | E16: =COORDENADAS!C6 -> 5500 | F16: =COORDENADAS!B22 -> -7513.1 | G16: =COORDENADAS!C22 -> 2750 | H16: =SQRT((F16-D16)^2+(G16-E16)^2) -> 5500.0522 | I16: =ASENTAMIENTOS!E9 -> 0 | J16: =ASENTAMIENTOS!E25 -> 0 | K16: =ABS(I16-J16) -> 0 | L16: =IF(H16>0,K16/H16,"") -> 0 | M16: =IF($M$2>0,1/$M$2,"") -> 0.002 | N16: =IF(L16="","—",IF(L16<=M16,"✔ OK","✘ EXCEDE")) -> ✔ OK
A17: C6↔C7 | B17: =ASENTAMIENTOS!A10 -> 6 | C17: =ASENTAMIENTOS!A11 -> 7 | D17: =COORDENADAS!B7 -> -8250 | E17: =COORDENADAS!C7 -> -9526.3 | F17: =COORDENADAS!B8 -> -5500 | G17: =COORDENADAS!C8 -> -4763.1 | H17: =SQRT((F17-D17)^2+(G17-E17)^2) -> 5500.0522 | I17: =ASENTAMIENTOS!E10 -> 0 | J17: =ASENTAMIENTOS!E11 -> 0 | K17: =ABS(I17-J17) -> 0 | L17: =IF(H17>0,K17/H17,"") -> 0 | M17: =IF($M$2>0,1/$M$2,"") -> 0.002 | N17: =IF(L17="","—",IF(L17<=M17,"✔ OK","✘ EXCEDE")) -> ✔ OK
A18: C6↔C19 | B18: =ASENTAMIENTOS!A10 -> 6 | C18: =ASENTAMIENTOS!A23 -> 19 | D18: =COORDENADAS!B7 -> -8250 | E18: =COORDENADAS!C7 -> -9526.3 | F18: =COORDENADAS!B20 -> -13013.165 | G18: =COORDENADAS!C20 -> -6776.2915 | H18: =SQRT((F18-D18)^2+(G18-E18)^2) -> 5500.0261 | I18: =ASENTAMIENTOS!E10 -> 0 | J18: =ASENTAMIENTOS!E23 -> 0 | K18: =ABS(I18-J18) -> 0 | L18: =IF(H18>0,K18/H18,"") -> 0 | M18: =IF($M$2>0,1/$M$2,"") -> 0.002 | N18: =IF(L18="","—",IF(L18<=M18,"✔ OK","✘ EXCEDE")) -> ✔ OK
A19: C6↔C82 | B19: =ASENTAMIENTOS!A10 -> 6 | C19: =ASENTAMIENTOS!A77 -> 82 | D19: =COORDENADAS!B7 -> -8250 | E19: =COORDENADAS!C7 -> -9526.3 | F19: =COORDENADAS!B29 -> -2750 | G19: =COORDENADAS!C29 -> -9526.3 | H19: =SQRT((F19-D19)^2+(G19-E19)^2) -> 5500 | I19: =ASENTAMIENTOS!E10 -> 0 | J19: =ASENTAMIENTOS!E77 -> 0 | K19: =ABS(I19-J19) -> 0 | L19: =IF(H19>0,K19/H19,"") -> 0 | M19: =IF($M$2>0,1/$M$2,"") -> 0.002 | N19: =IF(L19="","—",IF(L19<=M19,"✔ OK","✘ EXCEDE")) -> ✔ OK
A20: C7↔C8 | B20: =ASENTAMIENTOS!A11 -> 7 | C20: =ASENTAMIENTOS!A12 -> 8 | D20: =COORDENADAS!B8 -> -5500 | E20: =COORDENADAS!C8 -> -4763.1 | F20: =COORDENADAS!B9 -> -2750 | G20: =COORDENADAS!C9 -> 0 | H20: =SQRT((F20-D20)^2+(G20-E20)^2) -> 5499.9656 | I20: =ASENTAMIENTOS!E11 -> 0 | J20: =ASENTAMIENTOS!E12 -> 0 | K20: =ABS(I20-J20) -> 0 | L20: =IF(H20>0,K20/H20,"") -> 0 | M20: =IF($M$2>0,1/$M$2,"") -> 0.002 | N20: =IF(L20="","—",IF(L20<=M20,"✔ OK","✘ EXCEDE")) -> ✔ OK
A21: C7↔C20 | B21: =ASENTAMIENTOS!A11 -> 7 | C21: =ASENTAMIENTOS!A24 -> 20 | D21: =COORDENADAS!B8 -> -5500 | E21: =COORDENADAS!C8 -> -4763.1 | F21: =COORDENADAS!B21 -> -10263.117 | G21: =COORDENADAS!C21 -> -2013.119 | H21: =SQRT((F21-D21)^2+(G21-E21)^2) -> 5499.9708 | I21: =ASENTAMIENTOS!E11 -> 0 | J21: =ASENTAMIENTOS!E24 -> 0 | K21: =ABS(I21-J21) -> 0 | L21: =IF(H21>0,K21/H21,"") -> 0 | M21: =IF($M$2>0,1/$M$2,"") -> 0.002 | N21: =IF(L21="","—",IF(L21<=M21,"✔ OK","✘ EXCEDE")) -> ✔ OK
A22: C7↔C27 | B22: =ASENTAMIENTOS!A11 -> 7 | C22: =ASENTAMIENTOS!A31 -> 27 | D22: =COORDENADAS!B8 -> -5500 | E22: =COORDENADAS!C8 -> -4763.1 | F22: =COORDENADAS!B28 -> 0 | G22: =COORDENADAS!C28 -> -4763.1 | H22: =SQRT((F22-D22)^2+(G22-E22)^2) -> 5500 | I22: =ASENTAMIENTOS!E11 -> 0 | J22: =ASENTAMIENTOS!E31 -> 0 | K22: =ABS(I22-J22) -> 0 | L22: =IF(H22>0,K22/H22,"") -> 0 | M22: =IF($M$2>0,1/$M$2,"") -> 0.002 | N22: =IF(L22="","—",IF(L22<=M22,"✔ OK","✘ EXCEDE")) -> ✔ OK
A23: C7↔C82 | B23: =ASENTAMIENTOS!A11 -> 7 | C23: =ASENTAMIENTOS!A77 -> 82 | D23: =COORDENADAS!B8 -> -5500 | E23: =COORDENADAS!C8 -> -4763.1 | F23: =COORDENADAS!B29 -> -2750 | G23: =COORDENADAS!C29 -> -9526.3 | H23: =SQRT((F23-D23)^2+(G23-E23)^2) -> 5500.0522 | I23: =ASENTAMIENTOS!E11 -> 0 | J23: =ASENTAMIENTOS!E77 -> 0 | K23: =ABS(I23-J23) -> 0 | L23: =IF(H23>0,K23/H23,"") -> 0 | M23: =IF($M$2>0,1/$M$2,"") -> 0.002 | N23: =IF(L23="","—",IF(L23<=M23,"✔ OK","✘ EXCEDE")) -> ✔ OK
A24: C8↔C9 | B24: =ASENTAMIENTOS!A12 -> 8 | C24: =ASENTAMIENTOS!A13 -> 9 | D24: =COORDENADAS!B9 -> -2750 | E24: =COORDENADAS!C9 -> 0 | F24: =COORDENADAS!B10 -> 2750 | G24: =COORDENADAS!C10 -> 0 | H24: =SQRT((F24-D24)^2+(G24-E24)^2) -> 5500 | I24: =ASENTAMIENTOS!E12 -> 0 | J24: =ASENTAMIENTOS!E13 -> 0 | K24: =ABS(I24-J24) -> 0 | L24: =IF(H24>0,K24/H24,"") -> 0 | M24: =IF($M$2>0,1/$M$2,"") -> 0.002 | N24: =IF(L24="","—",IF(L24<=M24,"✔ OK","✘ EXCEDE")) -> ✔ OK
A25: C8↔C21 | B25: =ASENTAMIENTOS!A12 -> 8 | C25: =ASENTAMIENTOS!A25 -> 21 | D25: =COORDENADAS!B9 -> -2750 | E25: =COORDENADAS!C9 -> 0 | F25: =COORDENADAS!B22 -> -7513.1 | G25: =COORDENADAS!C22 -> 2750 | H25: =SQRT((F25-D25)^2+(G25-E25)^2) -> 5499.9656 | I25: =ASENTAMIENTOS!E12 -> 0 | J25: =ASENTAMIENTOS!E25 -> 0 | K25: =ABS(I25-J25) -> 0 | L25: =IF(H25>0,K25/H25,"") -> 0 | M25: =IF($M$2>0,1/$M$2,"") -> 0.002 | N25: =IF(L25="","—",IF(L25<=M25,"✔ OK","✘ EXCEDE")) -> ✔ OK
A26: C8↔C22 | B26: =ASENTAMIENTOS!A12 -> 8 | C26: =ASENTAMIENTOS!A26 -> 22 | D26: =COORDENADAS!B9 -> -2750 | E26: =COORDENADAS!C9 -> 0 | F26: =COORDENADAS!B23 -> -2750 | G26: =COORDENADAS!C23 -> 5500 | H26: =SQRT((F26-D26)^2+(G26-E26)^2) -> 5500 | I26: =ASENTAMIENTOS!E12 -> 0 | J26: =ASENTAMIENTOS!E26 -> 0 | K26: =ABS(I26-J26) -> 0 | L26: =IF(H26>0,K26/H26,"") -> 0 | M26: =IF($M$2>0,1/$M$2,"") -> 0.002 | N26: =IF(L26="","—",IF(L26<=M26,"✔ OK","✘ EXCEDE")) -> ✔ OK
A27: C8↔C27 | B27: =ASENTAMIENTOS!A12 -> 8 | C27: =ASENTAMIENTOS!A31 -> 27 | D27: =COORDENADAS!B9 -> -2750 | E27: =COORDENADAS!C9 -> 0 | F27: =COORDENADAS!B28 -> 0 | G27: =COORDENADAS!C28 -> -4763.1 | H27: =SQRT((F27-D27)^2+(G27-E27)^2) -> 5499.9656 | I27: =ASENTAMIENTOS!E12 -> 0 | J27: =ASENTAMIENTOS!E31 -> 0 | K27: =ABS(I27-J27) -> 0 | L27: =IF(H27>0,K27/H27,"") -> 0 | M27: =IF($M$2>0,1/$M$2,"") -> 0.002 | N27: =IF(L27="","—",IF(L27<=M27,"✔ OK","✘ EXCEDE")) -> ✔ OK
A28: C9↔C10 | B28: =ASENTAMIENTOS!A13 -> 9 | C28: =ASENTAMIENTOS!A14 -> 10 | D28: =COORDENADAS!B10 -> 2750 | E28: =COORDENADAS!C10 -> 0 | F28: =COORDENADAS!B11 -> 5500 | G28: =COORDENADAS!C11 -> -4763.1 | H28: =SQRT((F28-D28)^2+(G28-E28)^2) -> 5499.9656 | I28: =ASENTAMIENTOS!E13 -> 0 | J28: =ASENTAMIENTOS!E14 -> 0 | K28: =ABS(I28-J28) -> 0 | L28: =IF(H28>0,K28/H28,"") -> 0 | M28: =IF($M$2>0,1/$M$2,"") -> 0.002 | N28: =IF(L28="","—",IF(L28<=M28,"✔ OK","✘ EXCEDE")) -> ✔ OK
A29: C9↔C23 | B29: =ASENTAMIENTOS!A13 -> 9 | C29: =ASENTAMIENTOS!A27 -> 23 | D29: =COORDENADAS!B10 -> 2750 | E29: =COORDENADAS!C10 -> 0 | F29: =COORDENADAS!B24 -> 2750 | G29: =COORDENADAS!C24 -> 5500 | H29: =SQRT((F29-D29)^2+(G29-E29)^2) -> 5500 | I29: =ASENTAMIENTOS!E13 -> 0 | J29: =ASENTAMIENTOS!E27 -> 0 | K29: =ABS(I29-J29) -> 0 | L29: =IF(H29>0,K29/H29,"") -> 0 | M29: =IF($M$2>0,1/$M$2,"") -> 0.002 | N29: =IF(L29="","—",IF(L29<=M29,"✔ OK","✘ EXCEDE")) -> ✔ OK
A30: C9↔C24 | B30: =ASENTAMIENTOS!A13 -> 9 | C30: =ASENTAMIENTOS!A28 -> 24 | D30: =COORDENADAS!B10 -> 2750 | E30: =COORDENADAS!C10 -> 0 | F30: =COORDENADAS!B25 -> 7513.1 | G30: =COORDENADAS!C25 -> 2750 | H30: =SQRT((F30-D30)^2+(G30-E30)^2) -> 5499.9656 | I30: =ASENTAMIENTOS!E13 -> 0 | J30: =ASENTAMIENTOS!E28 -> 0 | K30: =ABS(I30-J30) -> 0 | L30: =IF(H30>0,K30/H30,"") -> 0 | M30: =IF($M$2>0,1/$M$2,"") -> 0.002 | N30: =IF(L30="","—",IF(L30<=M30,"✔ OK","✘ EXCEDE")) -> ✔ OK
A31: C9↔C27 | B31: =ASENTAMIENTOS!A13 -> 9 | C31: =ASENTAMIENTOS!A31 -> 27 | D31: =COORDENADAS!B10 -> 2750 | E31: =COORDENADAS!C10 -> 0 | F31: =COORDENADAS!B28 -> 0 | G31: =COORDENADAS!C28 -> -4763.1 | H31: =SQRT((F31-D31)^2+(G31-E31)^2) -> 5499.9656 | I31: =ASENTAMIENTOS!E13 -> 0 | J31: =ASENTAMIENTOS!E31 -> 0 | K31: =ABS(I31-J31) -> 0 | L31: =IF(H31>0,K31/H31,"") -> 0 | M31: =IF($M$2>0,1/$M$2,"") -> 0.002 | N31: =IF(L31="","—",IF(L31<=M31,"✔ OK","✘ EXCEDE")) -> ✔ OK
A32: C10↔C11 | B32: =ASENTAMIENTOS!A14 -> 10 | C32: =ASENTAMIENTOS!A15 -> 11 | D32: =COORDENADAS!B11 -> 5500 | E32: =COORDENADAS!C11 -> -4763.1 | F32: =COORDENADAS!B12 -> 8250 | G32: =COORDENADAS!C12 -> -9526.3 | H32: =SQRT((F32-D32)^2+(G32-E32)^2) -> 5500.0522 | I32: =ASENTAMIENTOS!E14 -> 0 | J32: =ASENTAMIENTOS!E15 -> 0 | K32: =ABS(I32-J32) -> 0 | L32: =IF(H32>0,K32/H32,"") -> 0 | M32: =IF($M$2>0,1/$M$2,"") -> 0.002 | N32: =IF(L32="","—",IF(L32<=M32,"✔ OK","✘ EXCEDE")) -> ✔ OK
A33: C10↔C25 | B33: =ASENTAMIENTOS!A14 -> 10 | C33: =ASENTAMIENTOS!A29 -> 25 | D33: =COORDENADAS!B11 -> 5500 | E33: =COORDENADAS!C11 -> -4763.1 | F33: =COORDENADAS!B26 -> 10263.117 | G33: =COORDENADAS!C26 -> -2013.119 | H33: =SQRT((F33-D33)^2+(G33-E33)^2) -> 5499.9708 | I33: =ASENTAMIENTOS!E14 -> 0 | J33: =ASENTAMIENTOS!E29 -> 0 | K33: =ABS(I33-J33) -> 0 | L33: =IF(H33>0,K33/H33,"") -> 0 | M33: =IF($M$2>0,1/$M$2,"") -> 0.002 | N33: =IF(L33="","—",IF(L33<=M33,"✔ OK","✘ EXCEDE")) -> ✔ OK
A34: C10↔C27 | B34: =ASENTAMIENTOS!A14 -> 10 | C34: =ASENTAMIENTOS!A31 -> 27 | D34: =COORDENADAS!B11 -> 5500 | E34: =COORDENADAS!C11 -> -4763.1 | F34: =COORDENADAS!B28 -> 0 | G34: =COORDENADAS!C28 -> -4763.1 | H34: =SQRT((F34-D34)^2+(G34-E34)^2) -> 5500 | I34: =ASENTAMIENTOS!E14 -> 0 | J34: =ASENTAMIENTOS!E31 -> 0 | K34: =ABS(I34-J34) -> 0 | L34: =IF(H34>0,K34/H34,"") -> 0 | M34: =IF($M$2>0,1/$M$2,"") -> 0.002 | N34: =IF(L34="","—",IF(L34<=M34,"✔ OK","✘ EXCEDE")) -> ✔ OK
A35: C10↔C83 | B35: =ASENTAMIENTOS!A14 -> 10 | C35: =ASENTAMIENTOS!A78 -> 83 | D35: =COORDENADAS!B11 -> 5500 | E35: =COORDENADAS!C11 -> -4763.1 | F35: =COORDENADAS!B30 -> 2750 | G35: =COORDENADAS!C30 -> -9526.3 | H35: =SQRT((F35-D35)^2+(G35-E35)^2) -> 5500.0522 | I35: =ASENTAMIENTOS!E14 -> 0 | J35: =ASENTAMIENTOS!E78 -> 0 | K35: =ABS(I35-J35) -> 0 | L35: =IF(H35>0,K35/H35,"") -> 0 | M35: =IF($M$2>0,1/$M$2,"") -> 0.002 | N35: =IF(L35="","—",IF(L35<=M35,"✔ OK","✘ EXCEDE")) -> ✔ OK
A36: C11↔C26 | B36: =ASENTAMIENTOS!A15 -> 11 | C36: =ASENTAMIENTOS!A30 -> 26 | D36: =COORDENADAS!B12 -> 8250 | E36: =COORDENADAS!C12 -> -9526.3 | F36: =COORDENADAS!B27 -> 13013.165 | G36: =COORDENADAS!C27 -> -6776.2915 | H36: =SQRT((F36-D36)^2+(G36-E36)^2) -> 5500.0261 | I36: =ASENTAMIENTOS!E15 -> 0 | J36: =ASENTAMIENTOS!E30 -> 0 | K36: =ABS(I36-J36) -> 0 | L36: =IF(H36>0,K36/H36,"") -> 0 | M36: =IF($M$2>0,1/$M$2,"") -> 0.002 | N36: =IF(L36="","—",IF(L36<=M36,"✔ OK","✘ EXCEDE")) -> ✔ OK
A37: C11↔C83 | B37: =ASENTAMIENTOS!A15 -> 11 | C37: =ASENTAMIENTOS!A78 -> 83 | D37: =COORDENADAS!B12 -> 8250 | E37: =COORDENADAS!C12 -> -9526.3 | F37: =COORDENADAS!B30 -> 2750 | G37: =COORDENADAS!C30 -> -9526.3 | H37: =SQRT((F37-D37)^2+(G37-E37)^2) -> 5500 | I37: =ASENTAMIENTOS!E15 -> 0 | J37: =ASENTAMIENTOS!E78 -> 0 | K37: =ABS(I37-J37) -> 0 | L37: =IF(H37>0,K37/H37,"") -> 0 | M37: =IF($M$2>0,1/$M$2,"") -> 0.002 | N37: =IF(L37="","—",IF(L37<=M37,"✔ OK","✘ EXCEDE")) -> ✔ OK
A38: C12↔C13 | B38: =ASENTAMIENTOS!A16 -> 12 | C38: =ASENTAMIENTOS!A17 -> 13 | D38: =COORDENADAS!B13 -> 17776.3 | E38: =COORDENADAS!C13 -> -4026.3 | F38: =COORDENADAS!B14 -> 15026.3 | G38: =COORDENADAS!C14 -> 736.9 | H38: =SQRT((F38-D38)^2+(G38-E38)^2) -> 5500.0522 | I38: =ASENTAMIENTOS!E16 -> 0 | J38: =ASENTAMIENTOS!E17 -> 0 | K38: =ABS(I38-J38) -> 0 | L38: =IF(H38>0,K38/H38,"") -> 0 | M38: =IF($M$2>0,1/$M$2,"") -> 0.002 | N38: =IF(L38="","—",IF(L38<=M38,"✔ OK","✘ EXCEDE")) -> ✔ OK
A39: C12↔C26 | B39: =ASENTAMIENTOS!A16 -> 12 | C39: =ASENTAMIENTOS!A30 -> 26 | D39: =COORDENADAS!B13 -> 17776.3 | E39: =COORDENADAS!C13 -> -4026.3 | F39: =COORDENADAS!B27 -> 13013.165 | G39: =COORDENADAS!C27 -> -6776.2915 | H39: =SQRT((F39-D39)^2+(G39-E39)^2) -> 5499.9917 | I39: =ASENTAMIENTOS!E16 -> 0 | J39: =ASENTAMIENTOS!E30 -> 0 | K39: =ABS(I39-J39) -> 0 | L39: =IF(H39>0,K39/H39,"") -> 0 | M39: =IF($M$2>0,1/$M$2,"") -> 0.002 | N39: =IF(L39="","—",IF(L39<=M39,"✔ OK","✘ EXCEDE")) -> ✔ OK
A40: C13↔C14 | B40: =ASENTAMIENTOS!A17 -> 13 | C40: =ASENTAMIENTOS!A18 -> 14 | D40: =COORDENADAS!B14 -> 15026.3 | E40: =COORDENADAS!C14 -> 736.9 | F40: =COORDENADAS!B15 -> 12276.3 | G40: =COORDENADAS!C15 -> 5500 | H40: =SQRT((F40-D40)^2+(G40-E40)^2) -> 5499.9656 | I40: =ASENTAMIENTOS!E17 -> 0 | J40: =ASENTAMIENTOS!E18 -> 0 | K40: =ABS(I40-J40) -> 0 | L40: =IF(H40>0,K40/H40,"") -> 0 | M40: =IF($M$2>0,1/$M$2,"") -> 0.002 | N40: =IF(L40="","—",IF(L40<=M40,"✔ OK","✘ EXCEDE")) -> ✔ OK
...

Sheet RESUMEN POR NODO
A1: RESUMEN DE ASENTAMIENTO DIFERENCIAL MÁXIMO POR NODO
A2: Para cada nodo de columna, muestra su asentamiento y el máximo diferencial respecto a los nodos directamente conectados.
A4: NODO (Columna) | B4: ASENTAMIENTO (mm) | C4: Nº NODOS CONECTADOS | D4: Δs MÁX. CONECTADOS (mm) | E4: NODO CON Δs MÁX. | F4: DIST. ANGULAR MÁX. | G4: ¿CUMPLE?
A5: 1 | B5: =ASENTAMIENTOS!E5 -> 0 | C5: 3 | D5: =MAX(DIFERENCIALES!K5,DIFERENCIALES!K7,DIFERENCIALES!K6) -> 0 | E5: =IFERROR(IF(DIFERENCIALES!K5=MAX(DIFERENCIALES!K5,DIFERENCIALES!K7,DIFERENCIALES!K6),"3",IF(DIFERENCIALES!K7=MAX(DIFERENCIALES!K5,DIFERENCIALES!K7,DIFERENCIALES!K6),"19","6")),"—") -> 3 | F5: =IFERROR(MAX(DIFERENCIALES!L5,DIFERENCIALES!L7,DIFERENCIALES!L6),"") -> 0 | G5: =IF(F5="","—",IF(F5<=1/DIFERENCIALES!$M$2,"✔ OK","✘ EXCEDE")) -> ✔ OK
A6: 2 | B6: =ASENTAMIENTOS!E6 -> 0 | C6: 3 | D6: =MAX(DIFERENCIALES!K8,DIFERENCIALES!K10,DIFERENCIALES!K9) -> 0 | E6: =IFERROR(IF(DIFERENCIALES!K8=MAX(DIFERENCIALES!K8,DIFERENCIALES!K10,DIFERENCIALES!K9),"11",IF(DIFERENCIALES!K10=MAX(DIFERENCIALES!K8,DIFERENCIALES!K10,DIFERENCIALES!K9),"26","12")),"—") -> 11 | F6: =IFERROR(MAX(DIFERENCIALES!L8,DIFERENCIALES!L10,DIFERENCIALES!L9),"") -> 0 | G6: =IF(F6="","—",IF(F6<=1/DIFERENCIALES!$M$2,"✔ OK","✘ EXCEDE")) -> ✔ OK
A7: 3 | B7: =ASENTAMIENTOS!E7 -> 0 | C7: 3 | D7: =MAX(DIFERENCIALES!K5,DIFERENCIALES!K12,DIFERENCIALES!K11) -> 0 | E7: =IFERROR(IF(DIFERENCIALES!K5=MAX(DIFERENCIALES!K5,DIFERENCIALES!K12,DIFERENCIALES!K11),"1",IF(DIFERENCIALES!K12=MAX(DIFERENCIALES!K5,DIFERENCIALES!K12,DIFERENCIALES!K11),"19","4")),"—") -> 1 | F7: =IFERROR(MAX(DIFERENCIALES!L5,DIFERENCIALES!L12,DIFERENCIALES!L11),"") -> 0 | G7: =IF(F7="","—",IF(F7<=1/DIFERENCIALES!$M$2,"✔ OK","✘ EXCEDE")) -> ✔ OK
A8: 4 | B8: =ASENTAMIENTOS!E8 -> 0 | C8: 3 | D8: =MAX(DIFERENCIALES!K11,DIFERENCIALES!K13,DIFERENCIALES!K14) -> 0 | E8: =IFERROR(IF(DIFERENCIALES!K11=MAX(DIFERENCIALES!K11,DIFERENCIALES!K13,DIFERENCIALES!K14),"3",IF(DIFERENCIALES!K13=MAX(DIFERENCIALES!K11,DIFERENCIALES!K13,DIFERENCIALES!K14),"5","20")),"—") -> 3 | F8: =IFERROR(MAX(DIFERENCIALES!L11,DIFERENCIALES!L13,DIFERENCIALES!L14),"") -> 0 | G8: =IF(F8="","—",IF(F8<=1/DIFERENCIALES!$M$2,"✔ OK","✘ EXCEDE")) -> ✔ OK
A9: 5 | B9: =ASENTAMIENTOS!E9 -> 0 | C9: 3 | D9: =MAX(DIFERENCIALES!K13,DIFERENCIALES!K16,DIFERENCIALES!K15) -> 0 | E9: =IFERROR(IF(DIFERENCIALES!K13=MAX(DIFERENCIALES!K13,DIFERENCIALES!K16,DIFERENCIALES!K15),"4",IF(DIFERENCIALES!K16=MAX(DIFERENCIALES!K13,DIFERENCIALES!K16,DIFERENCIALES!K15),"21","17")),"—") -> 4 | F9: =IFERROR(MAX(DIFERENCIALES!L13,DIFERENCIALES!L16,DIFERENCIALES!L15),"") -> 0 | G9: =IF(F9="","—",IF(F9<=1/DIFERENCIALES!$M$2,"✔ OK","✘ EXCEDE")) -> ✔ OK
A10: 6 | B10: =ASENTAMIENTOS!E10 -> 0 | C10: 3 | D10: =MAX(DIFERENCIALES!K6,DIFERENCIALES!K18,DIFERENCIALES!K17) -> 0 | E10: =IFERROR(IF(DIFERENCIALES!K6=MAX(DIFERENCIALES!K6,DIFERENCIALES!K18,DIFERENCIALES!K17),"1",IF(DIFERENCIALES!K18=MAX(DIFERENCIALES!K6,DIFERENCIALES!K18,DIFERENCIALES!K17),"19","7")),"—") -> 1 | F10: =IFERROR(MAX(DIFERENCIALES!L6,DIFERENCIALES!L18,DIFERENCIALES!L17),"") -> 0 | G10: =IF(F10="","—",IF(F10<=1/DIFERENCIALES!$M$2,"✔ OK","✘ EXCEDE")) -> ✔ OK
A11: 7 | B11: =ASENTAMIENTOS!E11 -> 0 | C11: 3 | D11: =MAX(DIFERENCIALES!K17,DIFERENCIALES!K21,DIFERENCIALES!K20) -> 0 | E11: =IFERROR(IF(DIFERENCIALES!K17=MAX(DIFERENCIALES!K17,DIFERENCIALES!K21,DIFERENCIALES!K20),"6",IF(DIFERENCIALES!K21=MAX(DIFERENCIALES!K17,DIFERENCIALES!K21,DIFERENCIALES!K20),"20","8")),"—") -> 6 | F11: =IFERROR(MAX(DIFERENCIALES!L17,DIFERENCIALES!L21,DIFERENCIALES!L20),"") -> 0 | G11: =IF(F11="","—",IF(F11<=1/DIFERENCIALES!$M$2,"✔ OK","✘ EXCEDE")) -> ✔ OK
A12: 8 | B12: =ASENTAMIENTOS!E12 -> 0 | C12: 4 | D12: =MAX(DIFERENCIALES!K20,DIFERENCIALES!K25,DIFERENCIALES!K26,DIFERENCIALES!K24) -> 0 | E12: =IFERROR(IF(DIFERENCIALES!K20=MAX(DIFERENCIALES!K20,DIFERENCIALES!K25,DIFERENCIALES!K26,DIFERENCIALES!K24),"7",IF(DIFERENCIALES!K25=MAX(DIFERENCIALES!K20,DIFERENCIALES!K25,DIFERENCIALES!K26,DIFERENCIALES!K24),"21",IF(DIFERENCIALES!K26=MAX(DIFERENCIALES!K20,DIFERENCIALES!K25,DIFERENCIALES!K26,DIFERENCIALES!K24),"22","9"))),"—") -> 7 | F12: =IFERROR(MAX(DIFERENCIALES!L20,DIFERENCIALES!L25,DIFERENCIALES!L26,DIFERENCIALES!L24),"") -> 0 | G12: =IF(F12="","—",IF(F12<=1/DIFERENCIALES!$M$2,"✔ OK","✘ EXCEDE")) -> ✔ OK
A13: 9 | B13: =ASENTAMIENTOS!E13 -> 0 | C13: 4 | D13: =MAX(DIFERENCIALES!K24,DIFERENCIALES!K29,DIFERENCIALES!K30,DIFERENCIALES!K28) -> 0 | E13: =IFERROR(IF(DIFERENCIALES!K24=MAX(DIFERENCIALES!K24,DIFERENCIALES!K29,DIFERENCIALES!K30,DIFERENCIALES!K28),"8",IF(DIFERENCIALES!K29=MAX(DIFERENCIALES!K24,DIFERENCIALES!K29,DIFERENCIALES!K30,DIFERENCIALES!K28),"23",IF(DIFERENCIALES!K30=MAX(DIFERENCIALES!K24,DIFERENCIALES!K29,DIFERENCIALES!K30,DIFERENCIALES!K28),"24","10"))),"—") -> 8 | F13: =IFERROR(MAX(DIFERENCIALES!L24,DIFERENCIALES!L29,DIFERENCIALES!L30,DIFERENCIALES!L28),"") -> 0 | G13: =IF(F13="","—",IF(F13<=1/DIFERENCIALES!$M$2,"✔ OK","✘ EXCEDE")) -> ✔ OK
A14: 10 | B14: =ASENTAMIENTOS!E14 -> 0 | C14: 3 | D14: =MAX(DIFERENCIALES!K28,DIFERENCIALES!K33,DIFERENCIALES!K32) -> 0 | E14: =IFERROR(IF(DIFERENCIALES!K28=MAX(DIFERENCIALES!K28,DIFERENCIALES!K33,DIFERENCIALES!K32),"9",IF(DIFERENCIALES!K33=MAX(DIFERENCIALES!K28,DIFERENCIALES!K33,DIFERENCIALES!K32),"25","11")),"—") -> 9 | F14: =IFERROR(MAX(DIFERENCIALES!L28,DIFERENCIALES!L33,DIFERENCIALES!L32),"") -> 0 | G14: =IF(F14="","—",IF(F14<=1/DIFERENCIALES!$M$2,"✔ OK","✘ EXCEDE")) -> ✔ OK
A15: 11 | B15: =ASENTAMIENTOS!E15 -> 0 | C15: 3 | D15: =MAX(DIFERENCIALES!K32,DIFERENCIALES!K36,DIFERENCIALES!K8) -> 0 | E15: =IFERROR(IF(DIFERENCIALES!K32=MAX(DIFERENCIALES!K32,DIFERENCIALES!K36,DIFERENCIALES!K8),"10",IF(DIFERENCIALES!K36=MAX(DIFERENCIALES!K32,DIFERENCIALES!K36,DIFERENCIALES!K8),"26","2")),"—") -> 10 | F15: =IFERROR(MAX(DIFERENCIALES!L32,DIFERENCIALES!L36,DIFERENCIALES!L8),"") -> 0 | G15: =IF(F15="","—",IF(F15<=1/DIFERENCIALES!$M$2,"✔ OK","✘ EXCEDE")) -> ✔ OK
A16: 12 | B16: =ASENTAMIENTOS!E16 -> 0 | C16: 3 | D16: =MAX(DIFERENCIALES!K39,DIFERENCIALES!K38,DIFERENCIALES!K9) -> 0 | E16: =IFERROR(IF(DIFERENCIALES!K39=MAX(DIFERENCIALES!K39,DIFERENCIALES!K38,DIFERENCIALES!K9),"26",IF(DIFERENCIALES!K38=MAX(DIFERENCIALES!K39,DIFERENCIALES!K38,DIFERENCIALES!K9),"13","2")),"—") -> 26 | F16: =IFERROR(MAX(DIFERENCIALES!L39,DIFERENCIALES!L38,DIFERENCIALES!L9),"") -> 0 | G16: =IF(F16="","—",IF(F16<=1/DIFERENCIALES!$M$2,"✔ OK","✘ EXCEDE")) -> ✔ OK
A17: 13 | B17: =ASENTAMIENTOS!E17 -> 0 | C17: 3 | D17: =MAX(DIFERENCIALES!K40,DIFERENCIALES!K41,DIFERENCIALES!K38) -> 0 | E17: =IFERROR(IF(DIFERENCIALES!K40=MAX(DIFERENCIALES!K40,DIFERENCIALES!K41,DIFERENCIALES!K38),"14",IF(DIFERENCIALES!K41=MAX(DIFERENCIALES!K40,DIFERENCIALES!K41,DIFERENCIALES!K38),"25","12")),"—") -> 14 | F17: =IFERROR(MAX(DIFERENCIALES!L40,DIFERENCIALES!L41,DIFERENCIALES!L38),"") -> 0 | G17: =IF(F17="","—",IF(F17<=1/DIFERENCIALES!$M$2,"✔ OK","✘ EXCEDE")) -> ✔ OK
A18: 14 | B18: =ASENTAMIENTOS!E18 -> 0 | C18: 3 | D18: =MAX(DIFERENCIALES!K42,DIFERENCIALES!K43,DIFERENCIALES!K40) -> 0 | E18: =IFERROR(IF(DIFERENCIALES!K42=MAX(DIFERENCIALES!K42,DIFERENCIALES!K43,DIFERENCIALES!K40),"18",IF(DIFERENCIALES!K43=MAX(DIFERENCIALES!K42,DIFERENCIALES!K43,DIFERENCIALES!K40),"24","13")),"—") -> 18 | F18: =IFERROR(MAX(DIFERENCIALES!L42,DIFERENCIALES!L43,DIFERENCIALES!L40),"") -> 0 | G18: =IF(F18="","—",IF(F18<=1/DIFERENCIALES!$M$2,"✔ OK","✘ EXCEDE")) -> ✔ OK
A19: 15 | B19: =ASENTAMIENTOS!E19 -> 0 | C19: 3 | D19: =MAX(DIFERENCIALES!K44,DIFERENCIALES!K46,DIFERENCIALES!K45) -> 0 | E19: =IFERROR(IF(DIFERENCIALES!K44=MAX(DIFERENCIALES!K44,DIFERENCIALES!K46,DIFERENCIALES!K45),"16",IF(DIFERENCIALES!K46=MAX(DIFERENCIALES!K44,DIFERENCIALES!K46,DIFERENCIALES!K45),"23","18")),"—") -> 16 | F19: =IFERROR(MAX(DIFERENCIALES!L44,DIFERENCIALES!L46,DIFERENCIALES!L45),"") -> 0 | G19: =IF(F19="","—",IF(F19<=1/DIFERENCIALES!$M$2,"✔ OK","✘ EXCEDE")) -> ✔ OK
A20: 16 | B20: =ASENTAMIENTOS!E20 -> 0 | C20: 3 | D20: =MAX(DIFERENCIALES!K47,DIFERENCIALES!K48,DIFERENCIALES!K44) -> 0 | E20: =IFERROR(IF(DIFERENCIALES!K47=MAX(DIFERENCIALES!K47,DIFERENCIALES!K48,DIFERENCIALES!K44),"17",IF(DIFERENCIALES!K48=MAX(DIFERENCIALES!K47,DIFERENCIALES!K48,DIFERENCIALES!K44),"22","15")),"—") -> 17 | F20: =IFERROR(MAX(DIFERENCIALES!L47,DIFERENCIALES!L48,DIFERENCIALES!L44),"") -> 0 | G20: =IF(F20="","—",IF(F20<=1/DIFERENCIALES!$M$2,"✔ OK","✘ EXCEDE")) -> ✔ OK
A21: 17 | B21: =ASENTAMIENTOS!E21 -> 0 | C21: 4 | D21: =MAX(DIFERENCIALES!K15,DIFERENCIALES!K49,DIFERENCIALES!K50,DIFERENCIALES!K47) -> 0 | E21: =IFERROR(IF(DIFERENCIALES!K15=MAX(DIFERENCIALES!K15,DIFERENCIALES!K49,DIFERENCIALES!K50,DIFERENCIALES!K47),"5",IF(DIFERENCIALES!K49=MAX(DIFERENCIALES!K15,DIFERENCIALES!K49,DIFERENCIALES!K50,DIFERENCIALES!K47),"21",IF(DIFERENCIALES!K50=MAX(DIFERENCIALES!K15,DIFERENCIALES!K49,DIFERENCIALES!K50,DIFERENCIALES!K47),"22","16"))),"—") -> 5 | F21: =IFERROR(MAX(DIFERENCIALES!L15,DIFERENCIALES!L49,DIFERENCIALES!L50,DIFERENCIALES!L47),"") -> 0 | G21: =IF(F21="","—",IF(F21<=1/DIFERENCIALES!$M$2,"✔ OK","✘ EXCEDE")) -> ✔ OK
A22: 18 | B22: =ASENTAMIENTOS!E22 -> 0 | C22: 4 | D22: =MAX(DIFERENCIALES!K45,DIFERENCIALES!K51,DIFERENCIALES!K52,DIFERENCIALES!K42) -> 0 | E22: =IFERROR(IF(DIFERENCIALES!K45=MAX(DIFERENCIALES!K45,DIFERENCIALES!K51,DIFERENCIALES!K52,DIFERENCIALES!K42),"15",IF(DIFERENCIALES!K51=MAX(DIFERENCIALES!K45,DIFERENCIALES!K51,DIFERENCIALES!K52,DIFERENCIALES!K42),"23",IF(DIFERENCIALES!K52=MAX(DIFERENCIALES!K45,DIFERENCIALES!K51,DIFERENCIALES!K52,DIFERENCIALES!K42),"24","14"))),"—") -> 15 | F22: =IFERROR(MAX(DIFERENCIALES!L45,DIFERENCIALES!L51,DIFERENCIALES!L52,DIFERENCIALES!L42),"") -> 0 | G22: =IF(F22="","—",IF(F22<=1/DIFERENCIALES!$M$2,"✔ OK","✘ EXCEDE")) -> ✔ OK
A23: 19 | B23: =ASENTAMIENTOS!E23 -> 0 | C23: 4 | D23: =MAX(DIFERENCIALES!K7,DIFERENCIALES!K12,DIFERENCIALES!K18,DIFERENCIALES!K53) -> 0 | E23: =IFERROR(IF(DIFERENCIALES!K7=MAX(DIFERENCIALES!K7,DIFERENCIALES!K12,DIFERENCIALES!K18,DIFERENCIALES!K53),"1",IF(DIFERENCIALES!K12=MAX(DIFERENCIALES!K7,DIFERENCIALES!K12,DIFERENCIALES!K18,DIFERENCIALES!K53),"3",IF(DIFERENCIALES!K18=MAX(DIFERENCIALES!K7,DIFERENCIALES!K12,DIFERENCIALES!K18,DIFERENCIALES!K53),"6","20"))),"—") -> 1 | F23: =IFERROR(MAX(DIFERENCIALES!L7,DIFERENCIALES!L12,DIFERENCIALES!L18,DIFERENCIALES!L53),"") -> 0 | G23: =IF(F23="","—",IF(F23<=1/DIFERENCIALES!$M$2,"✔ OK","✘ EXCEDE")) -> ✔ OK
A24: 20 | B24: =ASENTAMIENTOS!E24 -> 0 | C24: 4 | D24: =MAX(DIFERENCIALES!K53,DIFERENCIALES!K14,DIFERENCIALES!K54,DIFERENCIALES!K21) -> 0 | E24: =IFERROR(IF(DIFERENCIALES!K53=MAX(DIFERENCIALES!K53,DIFERENCIALES!K14,DIFERENCIALES!K54,DIFERENCIALES!K21),"19",IF(DIFERENCIALES!K14=MAX(DIFERENCIALES!K53,DIFERENCIALES!K14,DIFERENCIALES!K54,DIFERENCIALES!K21),"4",IF(DIFERENCIALES!K54=MAX(DIFERENCIALES!K53,DIFERENCIALES!K14,DIFERENCIALES!K54,DIFERENCIALES!K21),"21","7"))),"—") -> 19 | F24: =IFERROR(MAX(DIFERENCIALES!L53,DIFERENCIALES!L14,DIFERENCIALES!L54,DIFERENCIALES!L21),"") -> 0 | G24: =IF(F24="","—",IF(F24<=1/DIFERENCIALES!$M$2,"✔ OK","✘ EXCEDE")) -> ✔ OK
A25: 21 | B25: =ASENTAMIENTOS!E25 -> 0 | C25: 5 | D25: =MAX(DIFERENCIALES!K54,DIFERENCIALES!K16,DIFERENCIALES!K49,DIFERENCIALES!K25,DIFERENCIALES!K55) -> 0 | E25: =IFERROR(IF(DIFERENCIALES!K54=MAX(DIFERENCIALES!K54,DIFERENCIALES!K16,DIFERENCIALES!K49,DIFERENCIALES!K25,DIFERENCIALES!K55),"20",IF(DIFERENCIALES!K16=MAX(DIFERENCIALES!K54,DIFERENCIALES!K16,DIFERENCIALES!K49,DIFERENCIALES!K25,DIFERENCIALES!K55),"5",IF(DIFERENCIALES!K49=MAX(DIFERENCIALES!K54,DIFERENCIALES!K16,DIFERENCIALES!K49,DIFERENCIALES!K25,DIFERENCIALES!K55),"17",IF(DIFERENCIALES!K25=MAX(DIFERENCIALES!K54,DIFERENCIALES!K16,DIFERENCIALES!K49,DIFERENCIALES!K25,DIFERENCIALES!K55),"8","22")))),"—") -> 20 | F25: =IFERROR(MAX(DIFERENCIALES!L54,DIFERENCIALES!L16,DIFERENCIALES!L49,DIFERENCIALES!L25,DIFERENCIALES!L55),"") -> 0 | G25: =IF(F25="","—",IF(F25<=1/DIFERENCIALES!$M$2,"✔ OK","✘ EXCEDE")) -> ✔ OK
A26: 22 | B26: =ASENTAMIENTOS!E26 -> 0 | C26: 5 | D26: =MAX(DIFERENCIALES!K55,DIFERENCIALES!K50,DIFERENCIALES!K26,DIFERENCIALES!K56,DIFERENCIALES!K48) -> 0 | E26: =IFERROR(IF(DIFERENCIALES!K55=MAX(DIFERENCIALES!K55,DIFERENCIALES!K50,DIFERENCIALES!K26,DIFERENCIALES!K56,DIFERENCIALES!K48),"21",IF(DIFERENCIALES!K50=MAX(DIFERENCIALES!K55,DIFERENCIALES!K50,DIFERENCIALES!K26,DIFERENCIALES!K56,DIFERENCIALES!K48),"17",IF(DIFERENCIALES!K26=MAX(DIFERENCIALES!K55,DIFERENCIALES!K50,DIFERENCIALES!K26,DIFERENCIALES!K56,DIFERENCIALES!K48),"8",IF(DIFERENCIALES!K56=MAX(DIFERENCIALES!K55,DIFERENCIALES!K50,DIFERENCIALES!K26,DIFERENCIALES!K56,DIFERENCIALES!K48),"23","16")))),"—") -> 21 | F26: =IFERROR(MAX(DIFERENCIALES!L55,DIFERENCIALES!L50,DIFERENCIALES!L26,DIFERENCIALES!L56,DIFERENCIALES!L48),"") -> 0 | G26: =IF(F26="","—",IF(F26<=1/DIFERENCIALES!$M$2,"✔ OK","✘ EXCEDE")) -> ✔ OK
A27: 23 | B27: =ASENTAMIENTOS!E27 -> 0 | C27: 5 | D27: =MAX(DIFERENCIALES!K56,DIFERENCIALES!K29,DIFERENCIALES!K57,DIFERENCIALES!K46,DIFERENCIALES!K51) -> 0 | E27: =IFERROR(IF(DIFERENCIALES!K56=MAX(DIFERENCIALES!K56,DIFERENCIALES!K29,DIFERENCIALES!K57,DIFERENCIALES!K46,DIFERENCIALES!K51),"22",IF(DIFERENCIALES!K29=MAX(DIFERENCIALES!K56,DIFERENCIALES!K29,DIFERENCIALES!K57,DIFERENCIALES!K46,DIFERENCIALES!K51),"9",IF(DIFERENCIALES!K57=MAX(DIFERENCIALES!K56,DIFERENCIALES!K29,DIFERENCIALES!K57,DIFERENCIALES!K46,DIFERENCIALES!K51),"24",IF(DIFERENCIALES!K46=MAX(DIFERENCIALES!K56,DIFERENCIALES!K29,DIFERENCIALES!K57,DIFERENCIALES!K46,DIFERENCIALES!K51),"15","18")))),"—") -> 22 | F27: =IFERROR(MAX(DIFERENCIALES!L56,DIFERENCIALES!L29,DIFERENCIALES!L57,DIFERENCIALES!L46,DIFERENCIALES!L51),"") -> 0 | G27: =IF(F27="","—",IF(F27<=1/DIFERENCIALES!$M$2,"✔ OK","✘ EXCEDE")) -> ✔ OK
A28: 24 | B28: =ASENTAMIENTOS!E28 -> 0 | C28: 5 | D28: =MAX(DIFERENCIALES!K57,DIFERENCIALES!K52,DIFERENCIALES!K43,DIFERENCIALES!K30,DIFERENCIALES!K58) -> 0 | E28: =IFERROR(IF(DIFERENCIALES!K57=MAX(DIFERENCIALES!K57,DIFERENCIALES!K52,DIFERENCIALES!K43,DIFERENCIALES!K30,DIFERENCIALES!K58),"23",IF(DIFERENCIALES!K52=MAX(DIFERENCIALES!K57,DIFERENCIALES!K52,DIFERENCIALES!K43,DIFERENCIALES!K30,DIFERENCIALES!K58),"18",IF(DIFERENCIALES!K43=MAX(DIFERENCIALES!K57,DIFERENCIALES!K52,DIFERENCIALES!K43,DIFERENCIALES!K30,DIFERENCIALES!K58),"14",IF(DIFERENCIALES!K30=MAX(DIFERENCIALES!K57,DIFERENCIALES!K52,DIFERENCIALES!K43,DIFERENCIALES!K30,DIFERENCIALES!K58),"9","25")))),"—") -> 23 | F28: =IFERROR(MAX(DIFERENCIALES!L57,DIFERENCIALES!L52,DIFERENCIALES!L43,DIFERENCIALES!L30,DIFERENCIALES!L58),"") -> 0 | G28: =IF(F28="","—",IF(F28<=1/DIFERENCIALES!$M$2,"✔ OK","✘ EXCEDE")) -> ✔ OK
A29: 25 | B29: =ASENTAMIENTOS!E29 -> 0 | C29: 4 | D29: =MAX(DIFERENCIALES!K58,DIFERENCIALES!K33,DIFERENCIALES!K59,DIFERENCIALES!K41) -> 0 | E29: =IFERROR(IF(DIFERENCIALES!K58=MAX(DIFERENCIALES!K58,DIFERENCIALES!K33,DIFERENCIALES!K59,DIFERENCIALES!K41),"24",IF(DIFERENCIALES!K33=MAX(DIFERENCIALES!K58,DIFERENCIALES!K33,DIFERENCIALES!K59,DIFERENCIALES!K41),"10",IF(DIFERENCIALES!K59=MAX(DIFERENCIALES!K58,DIFERENCIALES!K33,DIFERENCIALES!K59,DIFERENCIALES!K41),"26","13"))),"—") -> 24 | F29: =IFERROR(MAX(DIFERENCIALES!L58,DIFERENCIALES!L33,DIFERENCIALES!L59,DIFERENCIALES!L41),"") -> 0 | G29: =IF(F29="","—",IF(F29<=1/DIFERENCIALES!$M$2,"✔ OK","✘ EXCEDE")) -> ✔ OK
A30: 26 | B30: =ASENTAMIENTOS!E30 -> 0 | C30: 4 | D30: =MAX(DIFERENCIALES!K36,DIFERENCIALES!K59,DIFERENCIALES!K39,DIFERENCIALES!K10) -> 0 | E30: =IFERROR(IF(DIFERENCIALES!K36=MAX(DIFERENCIALES!K36,DIFERENCIALES!K59,DIFERENCIALES!K39,DIFERENCIALES!K10),"11",IF(DIFERENCIALES!K59=MAX(DIFERENCIALES!K36,DIFERENCIALES!K59,DIFERENCIALES!K39,DIFERENCIALES!K10),"25",IF(DIFERENCIALES!K39=MAX(DIFERENCIALES!K36,DIFERENCIALES!K59,DIFERENCIALES!K39,DIFERENCIALES!K10),"12","2"))),"—") -> 11 | F30: =IFERROR(MAX(DIFERENCIALES!L36,DIFERENCIALES!L59,DIFERENCIALES!L39,DIFERENCIALES!L10),"") -> 0 | G30: =IF(F30="","—",IF(F30<=1/DIFERENCIALES!$M$2,"✔ OK","✘ EXCEDE")) -> ✔ OK
A31: 27 | B31: =ASENTAMIENTOS!E31 -> 0 | C31: 6 | D31: =MAX(DIFERENCIALES!K27,DIFERENCIALES!K31,DIFERENCIALES!K22,DIFERENCIALES!K34,DIFERENCIALES!K60,DIFERENCIALES!K61) -> 0 | E31: =IFERROR(IF(DIFERENCIALES!K27=MAX(DIFERENCIALES!K27,DIFERENCIALES!K31,DIFERENCIALES!K22,DIFERENCIALES!K34,DIFERENCIALES!K60,DIFERENCIALES!K61),"8",IF(DIFERENCIALES!K31=MAX(DIFERENCIALES!K27,DIFERENCIALES!K31,DIFERENCIALES!K22,DIFERENCIALES!K34,DIFERENCIALES!K60,DIFERENCIALES!K61),"9",IF(DIFERENCIALES!K22=MAX(DIFERENCIALES!K27,DIFERENCIALES!K31,DIFERENCIALES!K22,DIFERENCIALES!K34,DIFERENCIALES!K60,DIFERENCIALES!K61),"7",IF(DIFERENCIALES!K34=MAX(DIFERENCIALES!K27,DIFERENCIALES!K31,DIFERENCIALES!K22,DIFERENCIALES!K34,DIFERENCIALES!K60,DIFERENCIALES!K61),"10",IF(DIFERENCIALES!K60=MAX(DIFERENCIALES!K27,DIFERENCIALES!K31,DIFERENCIALES!K22,DIFERENCIALES!K34,DIFERENCIALES!K60,DIFERENCIALES!K61),"82","83"))))),"—") -> 8 | F31: =IFERROR(MAX(DIFERENCIALES!L27,DIFERENCIALES!L31,DIFERENCIALES!L22,DIFERENCIALES!L34,DIFERENCIALES!L60,DIFERENCIALES!L61),"") -> 0 | G31: =IF(F31="","—",IF(F31<=1/DIFERENCIALES!$M$2,"✔ OK","✘ EXCEDE")) -> ✔ OK
A32: 82 | B32: =ASENTAMIENTOS!E77 -> 0 | C32: 4 | D32: =MAX(DIFERENCIALES!K23,DIFERENCIALES!K60,DIFERENCIALES!K19,DIFERENCIALES!K62) -> 0 | E32: =IFERROR(IF(DIFERENCIALES!K23=MAX(DIFERENCIALES!K23,DIFERENCIALES!K60,DIFERENCIALES!K19,DIFERENCIALES!K62),"7",IF(DIFERENCIALES!K60=MAX(DIFERENCIALES!K23,DIFERENCIALES!K60,DIFERENCIALES!K19,DIFERENCIALES!K62),"27",IF(DIFERENCIALES!K19=MAX(DIFERENCIALES!K23,DIFERENCIALES!K60,DIFERENCIALES!K19,DIFERENCIALES!K62),"6","83"))),"—") -> 7 | F32: =IFERROR(MAX(DIFERENCIALES!L23,DIFERENCIALES!L60,DIFERENCIALES!L19,DIFERENCIALES!L62),"") -> 0 | G32: =IF(F32="","—",IF(F32<=1/DIFERENCIALES!$M$2,"✔ OK","✘ EXCEDE")) -> ✔ OK
A33: 83 | B33: =ASENTAMIENTOS!E78 -> 0 | C33: 4 | D33: =MAX(DIFERENCIALES!K61,DIFERENCIALES!K62,DIFERENCIALES!K35,DIFERENCIALES!K37) -> 0 | E33: =IFERROR(IF(DIFERENCIALES!K61=MAX(DIFERENCIALES!K61,DIFERENCIALES!K62,DIFERENCIALES!K35,DIFERENCIALES!K37),"27",IF(DIFERENCIALES!K62=MAX(DIFERENCIALES!K61,DIFERENCIALES!K62,DIFERENCIALES!K35,DIFERENCIALES!K37),"82",IF(DIFERENCIALES!K35=MAX(DIFERENCIALES!K61,DIFERENCIALES!K62,DIFERENCIALES!K35,DIFERENCIALES!K37),"10","11"))),"—") -> 27 | F33: =IFERROR(MAX(DIFERENCIALES!L61,DIFERENCIALES!L62,DIFERENCIALES!L35,DIFERENCIALES!L37),"") -> 0 | G33: =IF(F33="","—",IF(F33<=1/DIFERENCIALES!$M$2,"✔ OK","✘ EXCEDE")) -> ✔ OK

Sheet COORDENADAS
A1: NODO | B1: X (mm) | C1: Y (mm)
A2: 1 | B2: -14600.9 | C2: -9526.3
A3: 2 | B3: 14600.9 | C3: -9526.3
A4: 3 | B4: -17776.3 | C4: -4026.3
A5: 4 | B5: -15026.3 | C5: 736.9
A6: 5 | B6: -12276.3 | C6: 5500
A7: 6 | B7: -8250 | C7: -9526.3
A8: 7 | B8: -5500 | C8: -4763.1
A9: 8 | B9: -2750 | C9: 0
A10: 9 | B10: 2750 | C10: 0
A11: 10 | B11: 5500 | C11: -4763.1
A12: 11 | B12: 8250 | C12: -9526.3
A13: 12 | B13: 17776.3 | C13: -4026.3
... A30: 83 | B30: 2750 | C30: -9526.3
